boxuser@Ubuntu22:~/EventLink$ cd..
cd..: command not found
vboxuser@Ubuntu22:~/EventLink$ cd ..
vboxuser@Ubuntu22:~$ sudo apt install python3 python3-pip python3-venv
[sudo] password for vboxuser: 
Reading package lists... Done
Building dependency tree... Done
Reading state information... Done
python3 is already the newest version (3.10.6-1~22.04.1).
python3-pip is already the newest version (22.0.2+dfsg-1ubuntu0.5).
The following additional packages will be installed:
  python3-pip-whl python3-setuptools-whl python3.10-venv
The following NEW packages will be installed:
  python3-pip-whl python3-setuptools-whl python3-venv
  python3.10-venv
0 upgraded, 4 newly installed, 0 to remove and 54 not upgraded.
Need to get 2,475 kB of archives.
After this operation, 2,891 kB of additional disk space will be used.
Do you want to continue? [Y/n] y
Get:1 http://ph.archive.ubuntu.com/ubuntu jammy-updates/universe amd64 python3-pip-whl all 22.0.2+dfsg-1ubuntu0.5 [1,680 kB]
Get:2 http://ph.archive.ubuntu.com/ubuntu jammy-updates/universe amd64 python3-setuptools-whl all 59.6.0-1.2ubuntu0.22.04.2 [788 kB]
Get:3 http://ph.archive.ubuntu.com/ubuntu jammy-updates/universe amd64 python3.10-venv amd64 3.10.12-1~22.04.8 [5,722 B]
Get:4 http://ph.archive.ubuntu.com/ubuntu jammy-updates/universe amd64 python3-venv amd64 3.10.6-1~22.04.1 [1,042 B]
Fetched 2,475 kB in 1min 13s (34.0 kB/s)                           
Selecting previously unselected package python3-pip-whl.
(Reading database ... 213394 files and directories currently install
ed.)
Preparing to unpack .../python3-pip-whl_22.0.2+dfsg-1ubuntu0.5_all.d
eb ...
Unpacking python3-pip-whl (22.0.2+dfsg-1ubuntu0.5) ...
Selecting previously unselected package python3-setuptools-whl.
Preparing to unpack .../python3-setuptools-whl_59.6.0-1.2ubuntu0.22.
04.2_all.deb ...
Unpacking python3-setuptools-whl (59.6.0-1.2ubuntu0.22.04.2) ...
Selecting previously unselected package python3.10-venv.
Preparing to unpack .../python3.10-venv_3.10.12-1~22.04.8_amd64.deb 
...
Unpacking python3.10-venv (3.10.12-1~22.04.8) ...
Selecting previously unselected package python3-venv.
Preparing to unpack .../python3-venv_3.10.6-1~22.04.1_amd64.deb ...
Unpacking python3-venv (3.10.6-1~22.04.1) ...
Setting up python3-setuptools-whl (59.6.0-1.2ubuntu0.22.04.2) ...
Setting up python3-pip-whl (22.0.2+dfsg-1ubuntu0.5) ...
Setting up python3.10-venv (3.10.12-1~22.04.8) ...
Setting up python3-venv (3.10.6-1~22.04.1) ...
vboxuser@Ubuntu22:~$ cd home/vboxuser/EventLink
bash: cd: home/vboxuser/EventLink: No such file or directory
vboxuser@Ubuntu22:~$ cd /home/vboxuser/EventLink
vboxuser@Ubuntu22:~/EventLink$ python3 -m venv eventlink
vboxuser@Ubuntu22:~/EventLink$ source env/bin/activate
bash: env/bin/activate: No such file or directory
vboxuser@Ubuntu22:~/EventLink$ source env/bin/activate
bash: env/bin/activate: No such file or directory
vboxuser@Ubuntu22:~/EventLink$ python3 -m venv eventlink
vboxuser@Ubuntu22:~/EventLink$ source env/bin/activate
bash: env/bin/activate: No such file or directory
vboxuser@Ubuntu22:~/EventLink$ ls
eventlink  exlogo.png  login.py   server.py  test_app.py
EventLink  homepg.py   README.md  signup.py  user_profile.py
vboxuser@Ubuntu22:~/EventLink$ python3 -m venv EventLink
vboxuser@Ubuntu22:~/EventLink$ source env/bin/activate
bash: env/bin/activate: No such file or directory
vboxuser@Ubuntu22:~/EventLink$ python3 -m venv env
vboxuser@Ubuntu22:~/EventLink$ source env/bin/activate
(env) vboxuser@Ubuntu22:~/EventLink$ cd ..
(env) vboxuser@Ubuntu22:~$ deactivate
vboxuser@Ubuntu22:~$ cd /home/vboxuser/EventLink
vboxuser@Ubuntu22:~/EventLink$ python3 -m venv eventlink
vboxuser@Ubuntu22:~/EventLink$ source eventlink/bin/activate
(eventlink) vboxuser@Ubuntu22:~/EventLink$ pip install flet fastapi uvicorn pymongo bcrypt httpx
Collecting flet
  Downloading flet-0.26.0-py3-none-any.whl (535 kB)
     ━━━━━━━━━━━━━━━━━━━━━━━━━ 535.4/535.4 KB 296.0 kB/s eta 0:00:00
Collecting fastapi
  Downloading fastapi-0.115.8-py3-none-any.whl (94 kB)
     ━━━━━━━━━━━━━━━━━━━━━━━━━━━ 94.8/94.8 KB 129.7 kB/s eta 0:00:00
Collecting uvicorn
  Downloading uvicorn-0.34.0-py3-none-any.whl (62 kB)
     ━━━━━━━━━━━━━━━━━━━━━━━━━━━ 62.3/62.3 KB 367.5 kB/s eta 0:00:00
Collecting pymongo
  Downloading pymongo-4.11.1-cp310-cp310-manylinux_2_17_x86_64.manylinux2014_x86_64.whl (1.2 MB)
     ━━━━━━━━━━━━━━━━━━━━━━━━━━━━━ 1.2/1.2 MB 165.8 kB/s eta 0:00:00
Collecting bcrypt
  Downloading bcrypt-4.2.1-cp39-abi3-manylinux_2_28_x86_64.whl (278 kB)
     ━━━━━━━━━━━━━━━━━━━━━━━━━ 278.6/278.6 KB 338.5 kB/s eta 0:00:00
Collecting httpx
  Downloading httpx-0.28.1-py3-none-any.whl (73 kB)
     ━━━━━━━━━━━━━━━━━━━━━━━━━━━ 73.5/73.5 KB 488.3 kB/s eta 0:00:00
Collecting oauthlib<4.0.0,>=3.2.2
  Downloading oauthlib-3.2.2-py3-none-any.whl (151 kB)
     ━━━━━━━━━━━━━━━━━━━━━━━━━ 151.7/151.7 KB 310.6 kB/s eta 0:00:00
Collecting repath<0.10.0,>=0.9.0
  Downloading repath-0.9.0-py3-none-any.whl (4.7 kB)
Collecting typing-extensions>=4.8.0
  Downloading typing_extensions-4.12.2-py3-none-any.whl (37 kB)
Collecting pydantic!=1.8,!=1.8.1,!=2.0.0,!=2.0.1,!=2.1.0,<3.0.0,>=1.7.4
  Downloading pydantic-2.10.6-py3-none-any.whl (431 kB)
     ━━━━━━━━━━━━━━━━━━━━━━━━━ 431.7/431.7 KB 444.5 kB/s eta 0:00:00
Collecting starlette<0.46.0,>=0.40.0
  Downloading starlette-0.45.3-py3-none-any.whl (71 kB)
     ━━━━━━━━━━━━━━━━━━━━━━━━━━━ 71.5/71.5 KB 353.6 kB/s eta 0:00:00
Collecting click>=7.0
  Downloading click-8.1.8-py3-none-any.whl (98 kB)
     ━━━━━━━━━━━━━━━━━━━━━━━━━━━ 98.2/98.2 KB 298.9 kB/s eta 0:00:00
Collecting h11>=0.8
  Downloading h11-0.14.0-py3-none-any.whl (58 kB)
     ━━━━━━━━━━━━━━━━━━━━━━━━━━━ 58.3/58.3 KB 220.2 kB/s eta 0:00:00
Collecting dnspython<3.0.0,>=1.16.0
  Downloading dnspython-2.7.0-py3-none-any.whl (313 kB)
     ━━━━━━━━━━━━━━━━━━━━━━━━━ 313.6/313.6 KB 293.0 kB/s eta 0:00:00
Collecting httpcore==1.*
  Downloading httpcore-1.0.7-py3-none-any.whl (78 kB)
     ━━━━━━━━━━━━━━━━━━━━━━━━━━━ 78.6/78.6 KB 363.2 kB/s eta 0:00:00
Collecting anyio
  Downloading anyio-4.8.0-py3-none-any.whl (96 kB)
     ━━━━━━━━━━━━━━━━━━━━━━━━━━━ 96.0/96.0 KB 145.1 kB/s eta 0:00:00
Collecting idna
  Downloading idna-3.10-py3-none-any.whl (70 kB)
     ━━━━━━━━━━━━━━━━━━━━━━━━━━━ 70.4/70.4 KB 232.8 kB/s eta 0:00:00
Collecting certifi
  Downloading certifi-2025.1.31-py3-none-any.whl (166 kB)
     ━━━━━━━━━━━━━━━━━━━━━━━━━ 166.4/166.4 KB 297.5 kB/s eta 0:00:00
Collecting pydantic-core==2.27.2
  Downloading pydantic_core-2.27.2-cp310-cp310-manylinux_2_17_x86_64.manylinux2014_x86_64.whl (2.0 MB)
     ━━━━━━━━━━━━━━━━━━━━━━━━━━━━━ 2.0/2.0 MB 217.9 kB/s eta 0:00:00
Collecting annotated-types>=0.6.0
  Downloading annotated_types-0.7.0-py3-none-any.whl (13 kB)
Collecting six>=1.9.0
  Downloading six-1.17.0-py2.py3-none-any.whl (11 kB)
Collecting exceptiongroup>=1.0.2
  Downloading exceptiongroup-1.2.2-py3-none-any.whl (16 kB)
Collecting sniffio>=1.1
  Downloading sniffio-1.3.1-py3-none-any.whl (10 kB)
Installing collected packages: typing-extensions, sniffio, six, oauthlib, idna, h11, exceptiongroup, dnspython, click, certifi, bcrypt, annotated-types, uvicorn, repath, pymongo, pydantic-core, httpcore, anyio, starlette, pydantic, httpx, flet, fastapi
Successfully installed annotated-types-0.7.0 anyio-4.8.0 bcrypt-4.2.1 certifi-2025.1.31 click-8.1.8 dnspython-2.7.0 exceptiongroup-1.2.2 fastapi-0.115.8 flet-0.26.0 h11-0.14.0 httpcore-1.0.7 httpx-0.28.1 idna-3.10 oauthlib-3.2.2 pydantic-2.10.6 pydantic-core-2.27.2 pymongo-4.11.1 repath-0.9.0 six-1.17.0 sniffio-1.3.1 starlette-0.45.3 typing-extensions-4.12.2 uvicorn-0.34.0
(eventlink) vboxuser@Ubuntu22:~/EventLink$ uvicorn server:app --reload
INFO:     Will watch for changes in these directories: ['/home/vboxuser/EventLink']
INFO:     Uvicorn running on http://127.0.0.1:8000 (Press CTRL+C to quit)
INFO:     Started reloader process [4715] using StatReload
Process SpawnProcess-1:
Traceback (most recent call last):
  File "/home/vboxuser/EventLink/eventlink/lib/python3.10/site-packages/pydantic/networks.py", line 925, in import_email_validator
    import email_validator
ModuleNotFoundError: No module named 'email_validator'

The above exception was the direct cause of the following exception:

Traceback (most recent call last):
  File "/usr/lib/python3.10/multiprocessing/process.py", line 314, in _bootstrap
    self.run()
  File "/usr/lib/python3.10/multiprocessing/process.py", line 108, in run
    self._target(*self._args, **self._kwargs)
  File "/home/vboxuser/EventLink/eventlink/lib/python3.10/site-packages/uvicorn/_subprocess.py", line 80, in subprocess_started
    target(sockets=sockets)
  File "/home/vboxuser/EventLink/eventlink/lib/python3.10/site-packages/uvicorn/server.py", line 66, in run
    return asyncio.run(self.serve(sockets=sockets))
  File "/usr/lib/python3.10/asyncio/runners.py", line 44, in run
    return loop.run_until_complete(main)
  File "/usr/lib/python3.10/asyncio/base_events.py", line 649, in run_until_complete
    return future.result()
  File "/home/vboxuser/EventLink/eventlink/lib/python3.10/site-packages/uvicorn/server.py", line 70, in serve
    await self._serve(sockets)
  File "/home/vboxuser/EventLink/eventlink/lib/python3.10/site-packages/uvicorn/server.py", line 77, in _serve
    config.load()
  File "/home/vboxuser/EventLink/eventlink/lib/python3.10/site-packages/uvicorn/config.py", line 435, in load
    self.loaded_app = import_from_string(self.app)
  File "/home/vboxuser/EventLink/eventlink/lib/python3.10/site-packages/uvicorn/importer.py", line 19, in import_from_string
    module = importlib.import_module(module_str)
  File "/usr/lib/python3.10/importlib/__init__.py", line 126, in import_module
    return _bootstrap._gcd_import(name[level:], package, level)
  File "<frozen importlib._bootstrap>", line 1050, in _gcd_import
  File "<frozen importlib._bootstrap>", line 1027, in _find_and_load
  File "<frozen importlib._bootstrap>", line 1006, in _find_and_load_unlocked
  File "<frozen importlib._bootstrap>", line 688, in _load_unlocked
  File "<frozen importlib._bootstrap_external>", line 883, in exec_module
  File "<frozen importlib._bootstrap>", line 241, in _call_with_frames_removed
  File "/home/vboxuser/EventLink/server.py", line 13, in <module>
    class UserRegister(BaseModel):
  File "/home/vboxuser/EventLink/eventlink/lib/python3.10/site-packages/pydantic/_internal/_model_construction.py", line 224, in __new__
    complete_model_class(
  File "/home/vboxuser/EventLink/eventlink/lib/python3.10/site-packages/pydantic/_internal/_model_construction.py", line 602, in complete_model_class
    schema = cls.__get_pydantic_core_schema__(cls, handler)
  File "/home/vboxuser/EventLink/eventlink/lib/python3.10/site-packages/pydantic/main.py", line 702, in __get_pydantic_core_schema__
    return handler(source)
  File "/home/vboxuser/EventLink/eventlink/lib/python3.10/site-packages/pydantic/_internal/_schema_generation_shared.py", line 84, in __call__
    schema = self._handler(source_type)
  File "/home/vboxuser/EventLink/eventlink/lib/python3.10/site-packages/pydantic/_internal/_generate_schema.py", line 610, in generate_schema
    schema = self._generate_schema_inner(obj)
  File "/home/vboxuser/EventLink/eventlink/lib/python3.10/site-packages/pydantic/_internal/_generate_schema.py", line 879, in _generate_schema_inner
    return self._model_schema(obj)
  File "/home/vboxuser/EventLink/eventlink/lib/python3.10/site-packages/pydantic/_internal/_generate_schema.py", line 691, in _model_schema
    {k: self._generate_md_field_schema(k, v, decorators) for k, v in fields.items()},
  File "/home/vboxuser/EventLink/eventlink/lib/python3.10/site-packages/pydantic/_internal/_generate_schema.py", line 691, in <dictcomp>
    {k: self._generate_md_field_schema(k, v, decorators) for k, v in fields.items()},
  File "/home/vboxuser/EventLink/eventlink/lib/python3.10/site-packages/pydantic/_internal/_generate_schema.py", line 1071, in _generate_md_field_schema
    common_field = self._common_field_schema(name, field_info, decorators)
  File "/home/vboxuser/EventLink/eventlink/lib/python3.10/site-packages/pydantic/_internal/_generate_schema.py", line 1263, in _common_field_schema
    schema = self._apply_annotations(
  File "/home/vboxuser/EventLink/eventlink/lib/python3.10/site-packages/pydantic/_internal/_generate_schema.py", line 2056, in _apply_annotations
    schema = get_inner_schema(source_type)
  File "/home/vboxuser/EventLink/eventlink/lib/python3.10/site-packages/pydantic/_internal/_schema_generation_shared.py", line 84, in __call__
    schema = self._handler(source_type)
  File "/home/vboxuser/EventLink/eventlink/lib/python3.10/site-packages/pydantic/_internal/_generate_schema.py", line 2035, in inner_handler
    from_property = self._generate_schema_from_property(obj, source_type)
  File "/home/vboxuser/EventLink/eventlink/lib/python3.10/site-packages/pydantic/_internal/_generate_schema.py", line 759, in _generate_schema_from_property
    schema = get_schema(
  File "/home/vboxuser/EventLink/eventlink/lib/python3.10/site-packages/pydantic/networks.py", line 965, in __get_pydantic_core_schema__
    import_email_validator()
  File "/home/vboxuser/EventLink/eventlink/lib/python3.10/site-packages/pydantic/networks.py", line 927, in import_email_validator
    raise ImportError('email-validator is not installed, run `pip install pydantic[email]`') from e
ImportError: email-validator is not installed, run `pip install pydantic[email]`

^CINFO:     Stopping reloader process [4715]
(eventlink) vboxuser@Ubuntu22:~/EventLink$ python3 login.py
Installing flet-desktop 0.26.0 package...OK
/home/vboxuser/.flet/bin/flet-0.26.0/flet/flet: error while loading shared libraries: libmpv.so.1: cannot open shared object file: No such file or directory
(eventlink) vboxuser@Ubuntu22:~/EventLink$ uvicorn server:app --reload
INFO:     Will watch for changes in these directories: ['/home/vboxuser/EventLink']
INFO:     Uvicorn running on http://127.0.0.1:8000 (Press CTRL+C to quit)
INFO:     Started reloader process [4816] using StatReload
Process SpawnProcess-1:
Traceback (most recent call last):
  File "/home/vboxuser/EventLink/eventlink/lib/python3.10/site-packages/pydantic/networks.py", line 925, in import_email_validator
    import email_validator
ModuleNotFoundError: No module named 'email_validator'

The above exception was the direct cause of the following exception:

Traceback (most recent call last):
  File "/usr/lib/python3.10/multiprocessing/process.py", line 314, in _bootstrap
    self.run()
  File "/usr/lib/python3.10/multiprocessing/process.py", line 108, in run
    self._target(*self._args, **self._kwargs)
  File "/home/vboxuser/EventLink/eventlink/lib/python3.10/site-packages/uvicorn/_subprocess.py", line 80, in subprocess_started
    target(sockets=sockets)
  File "/home/vboxuser/EventLink/eventlink/lib/python3.10/site-packages/uvicorn/server.py", line 66, in run
    return asyncio.run(self.serve(sockets=sockets))
  File "/usr/lib/python3.10/asyncio/runners.py", line 44, in run
    return loop.run_until_complete(main)
  File "/usr/lib/python3.10/asyncio/base_events.py", line 649, in run_until_complete
    return future.result()
  File "/home/vboxuser/EventLink/eventlink/lib/python3.10/site-packages/uvicorn/server.py", line 70, in serve
    await self._serve(sockets)
  File "/home/vboxuser/EventLink/eventlink/lib/python3.10/site-packages/uvicorn/server.py", line 77, in _serve
    config.load()
  File "/home/vboxuser/EventLink/eventlink/lib/python3.10/site-packages/uvicorn/config.py", line 435, in load
    self.loaded_app = import_from_string(self.app)
  File "/home/vboxuser/EventLink/eventlink/lib/python3.10/site-packages/uvicorn/importer.py", line 19, in import_from_string
    module = importlib.import_module(module_str)
  File "/usr/lib/python3.10/importlib/__init__.py", line 126, in import_module
    return _bootstrap._gcd_import(name[level:], package, level)
  File "<frozen importlib._bootstrap>", line 1050, in _gcd_import
  File "<frozen importlib._bootstrap>", line 1027, in _find_and_load
  File "<frozen importlib._bootstrap>", line 1006, in _find_and_load_unlocked
  File "<frozen importlib._bootstrap>", line 688, in _load_unlocked
  File "<frozen importlib._bootstrap_external>", line 883, in exec_module
  File "<frozen importlib._bootstrap>", line 241, in _call_with_frames_removed
  File "/home/vboxuser/EventLink/server.py", line 13, in <module>
    class UserRegister(BaseModel):
  File "/home/vboxuser/EventLink/eventlink/lib/python3.10/site-packages/pydantic/_internal/_model_construction.py", line 224, in __new__
    complete_model_class(
  File "/home/vboxuser/EventLink/eventlink/lib/python3.10/site-packages/pydantic/_internal/_model_construction.py", line 602, in complete_model_class
    schema = cls.__get_pydantic_core_schema__(cls, handler)
  File "/home/vboxuser/EventLink/eventlink/lib/python3.10/site-packages/pydantic/main.py", line 702, in __get_pydantic_core_schema__
    return handler(source)
  File "/home/vboxuser/EventLink/eventlink/lib/python3.10/site-packages/pydantic/_internal/_schema_generation_shared.py", line 84, in __call__
    schema = self._handler(source_type)
  File "/home/vboxuser/EventLink/eventlink/lib/python3.10/site-packages/pydantic/_internal/_generate_schema.py", line 610, in generate_schema
    schema = self._generate_schema_inner(obj)
  File "/home/vboxuser/EventLink/eventlink/lib/python3.10/site-packages/pydantic/_internal/_generate_schema.py", line 879, in _generate_schema_inner
    return self._model_schema(obj)
  File "/home/vboxuser/EventLink/eventlink/lib/python3.10/site-packages/pydantic/_internal/_generate_schema.py", line 691, in _model_schema
    {k: self._generate_md_field_schema(k, v, decorators) for k, v in fields.items()},
  File "/home/vboxuser/EventLink/eventlink/lib/python3.10/site-packages/pydantic/_internal/_generate_schema.py", line 691, in <dictcomp>
    {k: self._generate_md_field_schema(k, v, decorators) for k, v in fields.items()},
  File "/home/vboxuser/EventLink/eventlink/lib/python3.10/site-packages/pydantic/_internal/_generate_schema.py", line 1071, in _generate_md_field_schema
    common_field = self._common_field_schema(name, field_info, decorators)
  File "/home/vboxuser/EventLink/eventlink/lib/python3.10/site-packages/pydantic/_internal/_generate_schema.py", line 1263, in _common_field_schema
    schema = self._apply_annotations(
  File "/home/vboxuser/EventLink/eventlink/lib/python3.10/site-packages/pydantic/_internal/_generate_schema.py", line 2056, in _apply_annotations
    schema = get_inner_schema(source_type)
  File "/home/vboxuser/EventLink/eventlink/lib/python3.10/site-packages/pydantic/_internal/_schema_generation_shared.py", line 84, in __call__
    schema = self._handler(source_type)
  File "/home/vboxuser/EventLink/eventlink/lib/python3.10/site-packages/pydantic/_internal/_generate_schema.py", line 2035, in inner_handler
    from_property = self._generate_schema_from_property(obj, source_type)
  File "/home/vboxuser/EventLink/eventlink/lib/python3.10/site-packages/pydantic/_internal/_generate_schema.py", line 759, in _generate_schema_from_property
    schema = get_schema(
  File "/home/vboxuser/EventLink/eventlink/lib/python3.10/site-packages/pydantic/networks.py", line 965, in __get_pydantic_core_schema__
    import_email_validator()
  File "/home/vboxuser/EventLink/eventlink/lib/python3.10/site-packages/pydantic/networks.py", line 927, in import_email_validator
    raise ImportError('email-validator is not installed, run `pip install pydantic[email]`') from e
ImportError: email-validator is not installed, run `pip install pydantic[email]`
^CINFO:     Stopping reloader process [4816]
